Workbook

Sheet January 2026
A1: Meal Calculation - Food | L1: Shopping Calculation | R1: Shopping Wallet Status | V1: Meal Rate | Z1: Meal Calculation - Money
A2: Date | B2: Ariyan | C2: Waythin | D2: Raju | E2: Rabiul | F2: Ayon | G2: Rihan | H2: Safar | I2: Tanvir | L2: Date | M2: Amount | O2: Responsible | P2: Note | R2: Name | S2: Amount | T2: Required | W2: =ROUND(M34/A35, 2) -> 58.22 | Z2: Name | AA2: Meal | AB2: Total Cost | AC2: Received | AD2: Give/Take
A3: 46023 | L3: 46023 | R3: Ariyan | S3: =560+470+2450+160+100+500 -> 4240 | T3: 3000 | Z3: Ariyan | AA3: =B34 -> 53 | AB3: =AA3*W2 -> 3085.66 | AC3: =S3 -> 4240 | AD3: =AC3-AB3 -> 1154.34
A4: 46024 | L4: 46024 | R4: Waythin | S4: =3630+80+120+40 -> 3870 | T4: 3000 | Z4: Waythin | AA4: =C34 -> 45 | AB4: =AA4*W2 -> 2619.9 | AC4: =S4 -> 3870 | AD4: =AC4-AB4 -> 1250.1
A5: 46025 | L5: 46025 | R5: Raju | T5: 3000 | Z5: Raju | AA5: =D34 -> 18 | AB5: =AA5*W2 -> 1047.96 | AC5: =S5 | AD5: =AC5-AB5 -> -1047.96
A6: 46026 | L6: 46026 | M6: =3630 -> 3630 | O6: Waythin | P6: Monthly | R6: Rabiul | S6: =830+1000 -> 1830 | T6: 3000 | Z6: Rabiul | AA6: =E34 -> 21 | AB6: =AA6*W2 -> 1222.62 | AC6: =S6 -> 1830 | AD6: =AC6-AB6 -> 607.38
A7: 46027 | B7: 1 | C7: 1 | D7: 1 | F7: 1 | G7: 1 | H7: 2 | I7: 1 | L7: 46027 | M7: =560 -> 560 | O7: Ariyan | P7: Chicken | R7: Ayon | S7: =2000 -> 2000 | T7: 3000 | Z7: Ayon | AA7: =F34 -> 30 | AB7: =AA7*W2 -> 1746.6 | AC7: =S7 -> 2000 | AD7: =AC7-AB7 -> 253.4
A8: 46028 | B8: 2 | C8: 2 | D8: 2 | E8: 1 | F8: 1 | G8: 1 | H8: 2 | I8: 1 | L8: 46028 | R8: Rihan | T8: 3000 | Z8: Rihan | AA8: =G34 -> 29 | AB8: =AA8*W2 -> 1688.38 | AC8: =S8 | AD8: =AC8-AB8 -> -1688.38
A9: 46029 | B9: 2 | C9: 2 | D9: 1 | E9: 1 | F9: 1 | G9: 1 | H9: 1 | I9: 2 | L9: 46029 | M9: 470 | O9: Ariyan | P9: Chicken | R9: Safar | S9: =950+40+1100+500+1000 -> 3590 | T9: 3000 | Z9: Safar | AA9: =H34 -> 64 | AB9: =AA9*W2 -> 3726.08 | AC9: =S9 -> 3590 | AD9: =AC9-AB9 -> -136.08
A10: 46030 | B10: 2 | C10: 1 | D10: 2 | E10: 1 | F10: 1 | G10: 1 | H10: 2 | I10: 1 | L10: 46030 | M10: =830+2450+160 -> 3440 | O10: Rabiul + Ariyan | P10: Fish + Rice | R10: Tanvir | S10: =1000+650+520 -> 2170 | T10: 3000 | Z10: Tanvir | AA10: =I34 -> 32 | AB10: =AA10*W2 -> 1863.04 | AC10: =S10 -> 2170 | AD10: =AC10-AB10 -> 306.96
A11: 46031 | B11: 0 | C11: 1 | D11: 1 | E11: 1 | F11: 1 | G11: 0 | H11: 2 | I11: 2 | L11: 46031 | AA11: =J34 -> 0 | AB11: =AA11*W2 -> 0 | AC11: =S11 | AD11: =AC11-AB11 -> 0
A12: 46032 | B12: 0 | C12: 2 | D12: 1 | E12: 1 | F12: 1 | G12: 0 | H12: 2 | I12: 2 | L12: 46032 | R12: Total | S12: =SUM(S3:S11) -> 17700 | T12: =SUM(T2:T11) -> 24000 | Z12: Total | AA12: =SUM(AA2:AA11) -> 292 | AB12: =SUM(AB2:AB11) -> 17000.24 | AC12: =SUM(AC2:AC11) -> 17700 | AD12: =CEILING(AC12-AB12, 1) -> 700
A13: 46033 | B13: 0 | C13: 2 | D13: 0 | E13: 0 | F13: 1 | G13: 1 | H13: 3 | I13: 1 | L13: 46033
A14: 46034 | B14: 3 | C14: 2 | E14: 0 | G14: 1 | H14: 4 | I14: 2 | L14: 46034 | M14: =950 -> 950 | O14: Safar | P14: Chicken + Veg
A15: 46035 | B15: 4 | C15: 2 | E15: 0 | H15: 3 | I15: 2 | L15: 46035 | M15: =80 -> 80 | O15: Waythin | P15: Vim
A16: 46036 | B16: 4 | C16: 1 | E16: 1 | F16: 1 | G16: 1 | I16: 1 | L16: 46036
A17: 46037 | B17: 4 | C17: 2 | E17: 2 | F17: 1 | G17: 2 | I17: 1 | L17: 46037 | M17: =1000 -> 1000 | O17: Rabiul | P17: Fish
A18: 46038 | B18: 3 | C18: 2 | E18: 2 | F18: 1 | G18: 4 | I18: 1 | L18: 46038 | M18: =40 -> 40 | O18: Safar | P18: Chilli
A19: 46039 | B19: 4 | C19: 2 | E19: 1 | F19: 2 | G19: 4 | I19: 2 | L19: 46039 | M19: =650 -> 650 | O19: Tanvir | P19: Chicken + Egg
A20: 46040 | B20: 2 | C20: 2 | D20: 1 | E20: 2 | F20: 2 | G20: 2 | H20: 2 | I20: 2 | L20: 46040 | M20: =1000 -> 1000 | O20: Waythin + Rihan | P20: Veggies
A21: 46041 | B21: 2 | C21: 2 | E21: 1 | F21: 1 | G21: 2 | H21: 2 | I21: 2 | L21: 46041 | M21: =950 -> 950 | O21: Ariyan | P21: Oil
A22: 46042 | B22: 2 | C22: 2 | E22: 0 | F22: 1 | G22: 1 | H22: 2 | I22: 2 | L22: 46042 | M22: =530+290+280 -> 1100 | O22: Safar | P22: Chicken + Fish
A23: 46043 | B23: 3 | C23: 2 | E23: 0 | F23: 2 | G23: 1 | H23: 2 | I23: 1 | L23: 46043 | M23: =160 -> 160 | O23: Waythin | P23: Egg
A24: 46044 | B24: 2 | C24: 2 | E24: 0 | F24: 1 | G24: 1 | H24: 1 | I24: 2 | L24: 46044 | M24: =100 -> 100 | O24: Ariyan | P24: Onion
A25: 46045 | B25: 2 | C25: 2 | D25: 1 | E25: 1 | F25: 1 | H25: 4 | I25: 0 | L25: 46045 | M25: =360 -> 360 | O25: Safar + Sakib | P25: Veggies
A26: 46046 | D26: 1 | E26: 1 | F26: 2 | H26: 4 | L26: 46046
A27: 46047 | D27: 1 | E27: 0 | F27: 3 | G27: 1 | H27: 4 | L27: 46047
A28: 46048 | B28: 1 | C28: 1 | E28: 2 | F28: 2 | G28: 1 | H28: 2 | L28: 46048 | M28: =1000 -> 1000 | O28: Safar | P28: Chicken + Masala + Onion/Garlic/Ginger
A29: 46049 | B29: 2 | C29: 2 | E29: 1 | F29: 1 | G29: 1 | H29: 4 | I29: 1 | L29: 46049
A30: 46050 | B30: 2 | C30: 2 | E30: 1 | F30: 1 | G30: 1 | H30: 4 | L30: 46050 | M30: =690 -> 690 | O30: Rabiul+Ariyan | P30: Masala + Eggs
A31: 46051 | B31: 2 | C31: 2 | E31: 0 | F31: 1 | G31: 1 | H31: 4 | I31: 1 | L31: 46051 | M31: 1000 | O31: Ariyan | P31: Chicken + Fish
A32: 46052 | B32: 2 | C32: 2 | D32: 4 | E32: 1 | H32: 4 | L32: 46052 | M32: =520 -> 520 | O32: Tanvir | P32: Chicken + Masala + Veggies
A33: 46053 | B33: 2 | C33: 2 | D33: 2 | H33: 4 | I33: 2 | L33: 46053 | M33: =-(500+200) -> -700 | O33: Ariyan | P33: Leftover
A34: Total | B34: =SUM(B2:B33) -> 53 | C34: =SUM(C2:C33) -> 45 | D34: =SUM(D2:D33) -> 18 | E34: =SUM(E2:E33) -> 21 | F34: =SUM(F2:F33) -> 30 | G34: =SUM(G2:G33) -> 29 | H34: =SUM(H2:H33) -> 64 | I34: =SUM(I2:I33) -> 32 | J34: =SUM(J2:J33) -> 0 | L34: Total | M34: =SUM(M3:M33) -> 17000 | O34: BDT
A35: =SUM(B34:J34) -> 292
L37: Balance | M37: =S12-M34 -> 700 | O37: BDT

Sheet February 2026
A1: Meal Calculation - Food | L1: Shopping Calculation | R1: Shopping Wallet Status | V1: Meal Rate | Z1: Meal Calculation - Money
A2: Date | B2: Ariyan | C2: Waythin | D2: Raju | E2: Rabiul | F2: Ayon | G2: Rihan | H2: Safar | I2: Tanvir | J2: Sakib | L2: Date | M2: Amount | O2: Responsible | P2: Note | R2: Name | S2: Amount | T2: Required | W2: =ROUND(M37/A38, 2) -> 57.98 | Z2: Name | AA2: Meal | AB2: Total Cost | AC2: Received | AD2: Give/Take
A3: 46054 | B3: 2 | C3: 2 | G3: 1 | H3: 3 | I3: 1 | J3: 2 | L3: 46023 | M3: =700 -> 700 | O3: Ariyan | P3: Last Month Leftover | R3: Ariyan | S3: =2450+500+1530+100 -> 4580 | T3: 3000 | Z3: Ariyan | AA3: =B37 -> 39 | AB3: =AA3*W2 -> 2261.22 | AC3: =S3 -> 4580 | AD3: =(AC3-AB3)+'January 2026'!AD3 -> 3473.12
A4: 46055 | B4: 1 | C4: 2 | D4: 1 | E4: 1 | G4: 1 | H4: 2 | J4: 2 | L4: 46024 | M4: =2450+500 -> 2950 | O4: Ariyan | P4: Rice + Chicken + Veggies | R4: Waythin | S4: =270+2000 -> 2270 | T4: 3000 | Z4: Waythin | AA4: =C37 -> 36.5 | AB4: =AA4*W2 -> 2116.27 | AC4: =S4 -> 2270 | AD4: =(AC4-AB4)+'January 2026'!AD4 -> 1403.83
A5: 46056 | B5: 2 | C5: 2 | G5: 2 | H5: 3 | I5: 1 | J5: 2 | L5: 46025 | R5: Raju | S5: =1400 -> 1400 | T5: 3000 | Z5: Raju | AA5: =D37 -> 5 | AB5: =AA5*W2 -> 289.9 | AC5: =S5 -> 1400 | AD5: =(AC5-AB5)+'January 2026'!AD5 -> 62.14
A6: 46057 | B6: 2 | C6: 2 | G6: 2 | H6: 2 | I6: 1 | J6: 2 | L6: 46026 | M6: =1530 -> 1530 | O6: Ariyan | P6: Oil + Masala + Ginger + Onion | R6: Rabiul | S6: =1040 -> 1040 | T6: 3000 | Z6: Rabiul | AA6: =E37 -> 24 | AB6: =AA6*W2 -> 1391.52 | AC6: =S6 -> 1040 | AD6: =(AC6-AB6)+'January 2026'!AD6 -> 255.86
A7: 46058 | B7: 2 | C7: 2 | G7: 2 | H7: 2 | I7: 1 | J7: 2 | L7: 46027 | M7: =480 -> 480 | O7: Rihan + Safar | R7: Ayon | T7: 3000 | Z7: Ayon | AA7: =F37 -> 18 | AB7: =AA7*W2 -> 1043.64 | AC7: =S7 | AD7: =(AC7-AB7)+'January 2026'!AD7 -> -790.24
A8: 46059 | B8: 2 | C8: 2 | G8: 2 | H8: 2 | J8: 2 | L8: 46028 | M8: =270 -> 270 | O8: Waythin | P8: Veggies | R8: Rihan | S8: =2600+200-400 -> 2400 | T8: 3000 | Z8: Rihan | AA8: =G37 -> 51.5 | AB8: =AA8*W2 -> 2985.97 | AC8: =S8 -> 2400 | AD8: =(AC8-AB8)+'January 2026'!AD8 -> -2274.35
A9: 46060 | C9: 2 | G9: 2 | H9: 2 | J9: 1 | L9: 46029 | M9: =100 -> 100 | O9: Ariyan | P9: Egg | R9: Safar | S9: =270 -> 270 | T9: 3000 | Z9: Safar | AA9: =H37 -> 22 | AB9: =AA9*W2 -> 1275.56 | AC9: =S9 -> 270 | AD9: =(AC9-AB9)+'January 2026'!AD9 -> -1141.64
A10: 46061 | C10: 1 | G10: 1 | H10: 1 | J10: 1 | L10: 46030 | R10: Tanvir | S10: =1500+430+370+500 -> 2800 | T10: 3000 | Z10: Tanvir | AA10: =I37 -> 28 | AB10: =AA10*W2 -> 1623.44 | AC10: =S10 -> 2800 | AD10: =(AC10-AB10)+'January 2026'!AD10 -> 1483.52
A11: 46062 | C11: 0.5 | G11: 0.5 | J11: 0.5 | L11: 46031 | M11: =270 -> 270 | O11: Safar | P11: Chicken | R11: Sakib | S11: =480+1200+210 -> 1890 | Z11: Sakib | AA11: =J37 -> 40.5 | AB11: =AA11*W2 -> 2348.19 | AC11: =S11 -> 1890 | AD11: =(AC11-AB11)+'January 2026'!AD11 -> -458.19
A12: 46063 | C12: 2 | G12: 2 | J12: 2 | L12: 46032 | R12: Total | S12: =SUM(S3:S11) -> 16650 | T12: =SUM(T2:T11) -> 24000 | Z12: Total | AA12: =SUM(AA2:AA11) -> 264.5 | AB12: =SUM(AB2:AB11) -> 15335.71 | AC12: =SUM(AC2:AC11) -> 16650 | AD12: =CEILING(AC12-AB12, 1)+'January 2026'!AD12 -> 2015
A13: 46064 | L13: 46033
A14: 46065 | L14: 46034
A15: 46066 | L15: 46035
A16: 46067 | L16: 46036
A17: 46068 | L17: 46037
A18: 46069 | B18: 1 | C18: 1 | D18: 2 | E18: 1 | G18: 1 | J18: 1 | L18: 46038
A19: 46070 | B19: 3 | C19: 2 | D19: 2 | G19: 2 | J19: 1 | L19: 46039 | M19: 1500 | O19: Ariyan | P19: Chicken + Veggies + Chillies
A20: 46071 | B20: 3 | C20: 3 | E20: 2 | G20: 4 | I20: 2 | J20: 2 | L20: 46040 | M20: =1000 -> 1000 | O20: Ariyan + Sakib +Rihan | P20: * Chola, Muri, Beshon, Dal, Masala, Mustard Oil
A21: 46072 | B21: 2 | C21: 1 | E21: 2 | G21: 3 | I21: 2 | J21: 2 | L21: 46041 | M21: =240 -> 240 | O21: Rihan | P21: * Beguni, Chola, Burinda, Jilapi
A22: 46073 | B22: 1 | E22: 1 | G22: 1 | J22: 1 | L22: 46042 | M22: =260+130 -> 390 | O22: Ariyan + Rabiul | P22: * Beguni , Pakora , Jilapi , Fruits
B23: 1 | C23: 1 | E23: 1 | G23: 2 | I23: 3 | J23: 1 | M23: =430 -> 430 | O23: Tanvir | P23: Chicken + Veggies
A24: 46074 | B24: 2 | C24: 3 | E24: 2 | G24: 3 | I24: 2 | J24: 2 | L24: 46043 | M24: =500 -> 500 | O24: Rihan + Sakib | P24: * Beguni , Roll , Apples
A25: 46075 | B25: 1 | E25: 1 | G25: 1 | J25: 1 | L25: 46044 | M25: =100+120+40+ 60 -> 320 | O25: Ariyan + Rihan | P25: * Chola , Piyaju , Kabab , Porota, Jilapi
B26: 1 | C26: 1 | E26: 1 | F26: 1 | G26: 2 | I26: 1 | J26: 1 | M26: =1040+265 -> 1305 | O26: Rabiul + Ariyan + Sakib | P26: Fish + Veggies
A27: 46076 | B27: 2 | C27: 1 | F27: 3 | G27: 3 | I27: 2 | J27: 2 | L27: 46045 | M27: =370 -> 370 | O27: Tanvir | P27: Egg + Potato + Veggies
A28: 46077 | B28: 1 | F28: 2 | G28: 1 | I28: 1 | J28: 1 | L28: 46046 | M28: =100+260+140 -> 500 | O28: Ariyan+Rihan
B29: 1 | C29: 1 | E29: 1 | F29: 1 | G29: 2 | I29: 1 | J29: 1 | M29: =600+210 -> 810 | O29: Ariyan+ Rihan+ Sakib | P29: Chicken + Sugar
A30: 46078 | B30: 2 | C30: 1 | E30: 1 | F30: 3 | G30: 2 | H30: 2 | I30: 2 | J30: 2 | L30: 46047 | M30: =50 -> 50 | O30: Ariyan | P30: Chillies
A31: 46079 | B31: 2 | C31: 1 | E31: 4 | F31: 3 | G31: 3 | I31: 2 | J31: 2 | L31: 46048 | M31: =800 -> 800 | O31: Rihan | P31: * Doi, Kola, Muri , Chira, Lebu , Gajor, Shosha
A32: 46080 | B32: 3 | C32: 1 | E32: 4 | F32: 2 | G32: 3 | I32: 2 | J32: 2 | L32: 46049 | M32: =600 -> 600 | O32: Rihan + Sakib | P32: * Jilapi + Ispi + Egg + Piyaju + Tomato
A33: 46081 | B33: 2 | C33: 2 | E33: 2 | F33: 3 | G33: 3 | H33: 3 | I33: 4 | J33: 2 | L33: 46050 | M33: =880+40 -> 920 | O33: Rihan | P33: * Noodles + Kola + Peyaj + Kumra + Jilapi + Alu
L34: 46051
L35: 46052 | M35: =-700 -> -700 | O35: Ariyan | P35: Leftover
L36: 46053
A37: Total | B37: =SUM(B2:B36) -> 39 | C37: =SUM(C2:C36) -> 36.5 | D37: =SUM(D2:D36) -> 5 | E37: =SUM(E2:E36) -> 24 | F37: =SUM(F2:F36) -> 18 | G37: =SUM(G2:G36) -> 51.5 | H37: =SUM(H2:H36) -> 22 | I37: =SUM(I2:I36) -> 28 | J37: =SUM(J2:J36) -> 40.5 | L37: Total | M37: =SUM(M3:M36) -> 15335 | O37: BDT
A38: =SUM(B37:J37) -> 264.5
L40: Balance | M40: =(S12-M37)+'January 2026'!M37 -> 2015 | O40: BDT | P40: * Ramadan Bazar

Sheet March 2026
A1: Meal Calculation - Food | M1: Shopping Calculation | S1: Shopping Wallet Status | W1: Meal Rate | AA1: Meal Calculation - Money
A2: Date | B2: Ariyan | C2: Waythin | D2: Raju | E2: Rabiul | F2: Ayon | G2: Rihan | H2: Safar | I2: Sakib | J2: Tanvir | K2: Nafis | M2: Date | N2: Amount | P2: Responsible | Q2: Note | S2: Name | T2: Amount | U2: Required | X2: =ROUND(N34/A35, 2) -> 58.71 | AA2: Name | AB2: Meal | AC2: Total Cost | AD2: Received | AE2: Give/Take
A3: 46082 | B3: 2 | C3: 1 | F3: 2 | G3: 2 | H3: 2 | I3: 2 | J3: 2 | K3: 2 | M3: 46082 | N3: =700 + 2500 + 900 -> 4100 | P3: Ariyan + Safar | Q3: Last Month Leftover + Rice + Iftari + Chicken | S3: Ariyan | T3: =1585+500+500-1735+430-1791.79 -> -511.79 | U3: 3000 | AA3: Ariyan | AB3: =B34 -> 20 | AC3: =AB3*X2 -> 1174.2 | AD3: =T3 -> -511.79 | AE3: =(AD3-AC3)+'February 2026'!AD3 -> 1787.13
A4: 46083 | B4: 3 | C4: 1 | F4: 3 | G4: 2 | H4: 2 | I4: 2 | J4: 2 | K4: 2 | M4: 46083 | N4: =260+180 -> 440 | P4: Ariyan + Rihan | Q4: Iftar + Egg + Onion | S4: Waythin | T4: 0 | U4: 3000 | AA4: Waythin | AB4: =C34 -> 21 | AC4: =AB4*X2 -> 1232.91 | AD4: =T4 -> 0 | AE4: =(AD4-AC4)+'February 2026'!AD4 -> 170.92
A5: 46084 | B5: 2 | C5: 1 | E5: 1 | F5: 3 | G5: 4 | H5: 3 | I5: 2 | J5: 2 | K5: 2 | M5: 46084 | N5: =1000 -> 1000 | P5: Safar + Rihan | Q5: Iftar + Chicken | S5: Raju | T5: 0 | U5: 3000 | AA5: Raju | AB5: =D34 -> 1 | AC5: =AB5*X2 -> 58.71 | AD5: =T5 -> 0 | AE5: =(AD5-AC5)+'February 2026'!AD5 -> 3.43
A6: 46085 | B6: 2 | C6: 1 | D6: 1 | F6: 2 | G6: 2 | H6: 3 | I6: 2 | J6: 1 | K6: 2 | M6: 46085 | S6: Rabiul | T6: 0 | U6: 3000 | AA6: Rabiul | AB6: =E34 -> 3 | AC6: =AB6*X2 -> 176.13 | AD6: =T6 -> 0 | AE6: =(AD6-AC6)+'February 2026'!AD6 -> 79.73
A7: 46086 | B7: 2 | C7: 1 | F7: 3 | G7: 0 | H7: 3 | I7: 2 | J7: 3 | K7: 2 | M7: 46086 | N7: =1380 -> 1380 | P7: Tanvir | Q7: Iftar + Meal | S7: Ayon | T7: =2000-265 -> 1735 | U7: 3000 | AA7: Ayon | AB7: =F34 -> 21 | AC7: =AB7*X2 -> 1232.91 | AD7: =T7 -> 1735 | AE7: =(AD7-AC7)+'February 2026'!AD7 -> -288.15
A8: 46087 | B8: 0 | C8: 1 | F8: 2 | H8: 2 | I8: 1 | J8: 3 | K8: 2 | M8: 46087 | N8: =830 -> 830 | P8: Safar | Q8: Iftar + Meal | S8: Rihan | T8: =1940+415+475+320+200+190+100 -> 3640 | U8: 3000 | AA8: Rihan | AB8: =G34 -> 45 | AC8: =AB8*X2 -> 2641.95 | AD8: =T8 -> 3640 | AE8: =(AD8-AC8)+'February 2026'!AD8 -> -1276.3
A9: 46088 | C9: 1 | F9: 2 | H9: 1 | I9: 1 | J9: 2 | K9: 1 | M9: 46088 | N9: =415 -> 415 | P9: Rihan | Q9: Iftar | S9: Safar | T9: =400+100+500 -> 1000 | U9: 3000 | AA9: Safar | AB9: =H34 -> 29 | AC9: =AB9*X2 -> 1702.59 | AD9: =T9 -> 1000 | AE9: =(AD9-AC9)+'February 2026'!AD9 -> -1844.23
A10: 46089 | C10: 1 | F10: 2 | G10: 3 | H10: 3 | I10: 2 | J10: 2 | K10: 2 | M10: 46089 | N10: =930 -> 930 | P10: Nafis | Q10: Chicken + Vegetables | S10: Sakib | T10: =110+1791.79 -> 1901.79 | U10: 3000 | AA10: Sakib | AB10: =I34 -> 24 | AC10: =AB10*X2 -> 1409.04 | AD10: =T10 -> 1901.79 | AE10: =(AD10-AC10)+'February 2026'!AD11 -> 34.56
A11: 46090 | C11: 1 | F11: 2 | G11: 3 | H11: 4 | I11: 3 | J11: 2 | K11: 2 | M11: 46090 | N11: =475+180 -> 655 | P11: Nafis + Rihan | Q11: Milk + Banana + Onions + Salad | S11: Tanvir | T11: =1380 -> 1380 | U11: 3000 | AA11: Tanvir | AB11: =J34 -> 28 | AC11: =AB11*X2 -> 1643.88 | AD11: =T11 -> 1380 | AE11: =(AD11-AC11)+'February 2026'!AD10 -> 1219.64
A12: 46091 | C12: 1 | G12: 3 | H12: 3 | I12: 3 | J12: 2 | M12: 46091 | N12: =320+110 -> 430 | P12: Rihan + Sakib | Q12: Iftar | S12: Nafis | T12: =930+180 -> 1110 | U12: 3000 | AA12: Nafis | AB12: =K34 -> 17 | AC12: =AB12*X2 -> 998.07 | AD12: =T12 -> 1110 | AE12: =(AD12-AC12) -> 111.93
A13: 46092 | C13: 1 | G13: 3 | H13: 3 | I13: 2 | J13: 1 | M13: 46092 | S13: Total | T13: =SUM(T3:T12) -> 10255 | U13: =SUM(U3:U12) -> 30000 | AA13: Total | AB13: =SUM(AB3:AB12) -> 209 | AC13: =SUM(AC3:AC12) -> 12270.39 | AD13: =SUM(AD3:AD12) -> 10255 | AE13: =CEILING(AD13-AC13, 1)+'February 2026'!AD12 -> 0
A14: 46093 | B14: 2 | C14: 1 | G14: 4 | J14: 1 | M14: 46093
A15: 46094 | B15: 2 | C15: 1 | G15: 4 | J15: 1 | M15: 46094 | N15: =200+190 -> 390 | P15: Rihan | Q15: Iftar + Meal
A16: 46095 | C16: 1 | G16: 4 | M16: 46095 | N16: 100 | P16: Rihan | Q16: Veg
A17: 46096 | C17: 1 | G17: 4 | M17: 46096
A18: 46097 | C18: 1 | G18: 4 | M18: 46097
A19: 46098 | M19: 46098
A20: 46099 | M20: 46099
A21: 46100 | M21: 46100
A22: 46101 | M22: 46101
A23: 46102 | M23: 46102
A24: 46103 | M24: 46103
A25: 46104 | M25: 46104
A26: 46105 | M26: 46105
A27: 46106 | M27: 46106
A28: 46107 | M28: 46107
A29: 46108 | M29: 46108
A30: 46109 | B30: 1 | C30: 1 | E30: 1 | I30: 1 | M30: 46109 | N30: =700+300+600 -> 1600 | P30: Ariyan | Q30: Chicken + OIL + Veggies
A31: 46110 | B31: 1 | C31: 1 | G31: 1 | I31: 1 | J31: 1 | M31: 46110
A32: 46111 | B32: 1 | C32: 1 | G32: 1 | J32: 1 | M32: 46111
A33: 46112 | B33: 2 | C33: 2 | E33: 1 | G33: 1 | J33: 2 | M33: 46112
A34: Total | B34: =SUM(B2:B33) -> 20 | C34: =SUM(C2:C33) -> 21 | D34: =SUM(D2:D33) -> 1 | E34: =SUM(E2:E33) -> 3 | F34: =SUM(F2:F33) -> 21 | G34: =SUM(G2:G33) -> 45 | H34: =SUM(H2:H33) -> 29 | I34: =SUM(I2:I33) -> 24 | ... K34: =SUM(K2:K33) -> 17 | M34: Total | N34: =SUM(N3:N33) -> 12270 | P34: BDT
A35: =SUM(B34:K34) -> 209
M37: Balance | N37: =(T13-N34)+ 'February 2026'!M40 -> 0 | P37: BDT

Sheet April 2026
A1: Meal Calculation - Food | M1: Shopping Calculation | S1: Shopping Wallet Status | W1: Meal Rate | AA1: Meal Calculation - Money
A2: Date | B2: Ariyan | C2: Waythin | D2: Umid | F2: Ayon | G2: Rihan | H2: Safar | I2: Sakib | J2: Tanvir | K2: Nafis | M2: Date | N2: Amount | P2: Responsible | Q2: Note | S2: Name | T2: Amount | U2: Required | X2: =ROUND(N34/A35, 2) -> 54.09 | AA2: Name | AB2: Meal | AC2: Total Cost | AD2: Received | AE2: Give/Take
A3: 46113 | B3: 2 | C3: 2 | G3: 1 | H3: 2 | J3: 2 | M3: 46113 | N3: =750 -> 750 | P3: Tanvir | Q3: Egg + Veggies | S3: Ariyan | T3: =2990+1000+180+275+1440+1500 -> 7385 | U3: 3000 | AA3: Ariyan | AB3: =B34 -> 53 | AC3: =AB3*X2 -> 2866.77 | AD3: =T3 -> 7385 | AE3: =(AD3-AC3)+'March 2026'!AE3 -> 6305.36
A4: 46114 | B4: 2 | C4: 2 | G4: 1 | H4: 2 | J4: 2 | M4: 46114 | S4: Waythin | U4: 3000 | AA4: Waythin | AB4: =C34 -> 52 | AC4: =AB4*X2 -> 2812.68 | AD4: =T4 | AE4: =(AD4-AC4)+'March 2026'!AE4 -> -2641.76
A5: 46115 | J5: 2 | M5: 46115 | S5: Umid | U5: 3000 | AA5: Umid | AB5: =D34 -> 18 | AC5: =AB5*X2 -> 973.62 | AD5: =T5 | AE5: =(AD5-AC5) -> -973.62
A6: 46116 | J6: 2 | M6: 46116 | U6: 3000 | AB6: =E34 -> 0 | AC6: =AB6*X2 -> 0 | AD6: =T6 | AE6: =(AD6-AC6) -> 0
A7: 46117 | J7: 2 | M7: 46117 | S7: Ayon | T7: =476+500 -> 976 | U7: 3000 | AA7: Ayon | AB7: =F34 -> 9 | AC7: =AB7*X2 -> 486.81 | AD7: =T7 -> 976 | AE7: =(AD7-AC7)+'March 2026'!AE7 -> 201.04
A8: 46118 | G8: 2 | H8: 2 | J8: 2 | K8: 2 | M8: 46118 | S8: Rihan | T8: =1700+1142 -> 2842 | U8: 3000 | AA8: Rihan | AB8: =G34 -> 37 | AC8: =AB8*X2 -> 2001.33 | AD8: =T8 -> 2842 | AE8: =(AD8-AC8)+'March 2026'!AE8 -> -435.63
A9: 46119 | C9: 2 | G9: 2 | H9: 2 | J9: 1 | K9: 2 | M9: 46119 | N9: =1965 -> 1965 | P9: Tanvir | Q9: Fish + Spices + Veggies + Oil | S9: Safar | T9: =160+500 -> 660 | U9: 3000 | AA9: Safar | AB9: =H34 -> 56 | AC9: =AB9*X2 -> 3029.04 | AD9: =T9 -> 660 | AE9: =(AD9-AC9)+'March 2026'!AE9 -> -4213.27
A10: 46120 | B10: 2 | C10: 2 | D10: 1 | G10: 1 | H10: 2 | J10: 2 | K10: 2 | M10: 46120 | S10: Sakib | U10: 3000 | AB10: =I34 -> 0 | AC10: =AB10*X2 -> 0 | AD10: =T10 | AE10: =(AD10-AC10) -> 0
A11: 46121 | B11: 2 | C11: 2 | D11: 1 | G11: 1 | H11: 2 | J11: 2 | K11: 2 | M11: 46121 | N11: =2990 -> 2990 | P11: Ariyan | Q11: Rice + Oil + Eggs | S11: Tanvir | T11: =750+1965+290+235 -> 3240 | U11: 3000 | AA11: Tanvir | AB11: =J34 -> 41 | AC11: =AB11*X2 -> 2217.69 | AD11: =T11 -> 3240 | AE11: =(AD11-AC11)+'March 2026'!AE11 -> 2241.95
A12: 46122 | B12: 2 | C12: 2 | D12: 1 | G12: 1 | H12: 2 | J12: 3 | K12: 2 | M12: 46122 | S12: Nafis | T12: =925+610+360 -> 1895 | U12: 3000 | AA12: Nafis | AB12: =K34 -> 39 | AC12: =AB12*X2 -> 2109.51 | AD12: =T12 -> 1895 | AE12: =(AD12-AC12)+'March 2026'!AE12 -> -102.58
A13: 46123 | B13: 2 | C13: 2 | D13: 1 | H13: 2 | J13: 1 | K13: 2 | M13: 46123 | N13: =1000 -> 1000 | P13: Ariyan | Q13: Chicken + Veggies | S13: Total | T13: =SUM(T3:T12) -> 16998 | U13: =SUM(U3:U12) -> 30000 | AA13: Total | AB13: =SUM(AB3:AB12) -> 305 | AC13: =SUM(AC3:AC12) -> 16497.45 | AD13: =SUM(AD3:AD12) -> 16998 | AE13: =CEILING(AD13-AC13, 1)+'March 2026'!AE13 -> 501
A14: 46124 | B14: 2 | C14: 2 | D14: 1 | G14: 2 | H14: 4 | J14: 1 | K14: 2 | M14: 46124 | N14: 353 | P14: Ariyan | Q14: Veggies
A15: 46125 | B15: 3 | C15: 2 | D15: 1 | G15: 3 | H15: 2 | J15: 1 | K15: 2 | M15: 46125 | N15: 180 | P15: Ariyan | Q15: Eggs
A16: 46126 | B16: 4 | C16: 2 | D16: 1 | G16: 2 | H16: 3 | J16: 2 | K16: 3 | M16: 46126 | N16: =780 + 925 -> 1705 | P16: Safar + Nafis | Q16: Fish + Veggies
A17: 46127 | B17: 3 | C17: 2 | D17: 1 | G17: 2 | H17: 2 | J17: 1 | K17: 2 | M17: 46127
A18: 46128 | B18: 2 | C18: 2 | G18: 2 | H18: 3 | J18: 1 | K18: 2 | M18: 46128 | N18: =190 -> 190 | P18: Ariyan | Q18: Eggs
A19: 46129 | B19: 2 | C19: 2 | G19: 2 | H19: 2 | J19: 1 | K19: 2 | M19: 46129
A20: 46130 | B20: 2 | C20: 2 | G20: 2 | H20: 2 | J20: 1 | K20: 2 | M20: 46130 | N20: =610+290+160+1590 -> 2650 | P20: Nafis + Tanvir + Safar + Waythin | Q20: Chicken + Veggies + Shutki
A21: 46131 | B21: 2 | C21: 2 | G21: 1 | H21: 2 | J21: 1 | K21: 2 | M21: 46131
A22: 46132 | B22: 2 | C22: 2 | G22: 1 | H22: 2 | J22: 1 | K22: 2 | M22: 46132 | N22: =180 -> 180 | P22: Ariyan | Q22: Eggs
A23: 46133 | B23: 2 | C23: 2 | D23: 1 | G23: 1 | H23: 2 | J23: 1 | M23: 46133 | N23: =1500 -> 1500 | P23: Safar | Q23: Chicken + Fish
A24: 46134 | B24: 2 | C24: 2 | D24: 1 | G24: 1 | H24: 2 | J24: 1 | M24: 46134
A25: 46135 | B25: 2 | C25: 2 | D25: 1 | G25: 1 | H25: 2 | J25: 1 | M25: 46135
A26: 46136 | B26: 2 | C26: 2 | D26: 1 | F26: 3 | G26: 2 | H26: 1 | J26: 1 | M26: 46136 | N26: =1440 -> 1440 | P26: Ariyan | Q26: Oil + Chillies
A27: 46137 | B27: 1 | C27: 2 | D27: 1 | F27: 1 | G27: 2 | H27: 1 | J27: 1 | M27: 46137
A28: 46138 | B28: 2 | C28: 2 | D28: 1 | F28: 1 | G28: 0 | H28: 2 | J28: 1 | M28: 46138
A29: 46139 | B29: 2 | C29: 2 | D29: 1 | F29: 1 | G29: 1 | H29: 2 | J29: 1 | K29: 2 | M29: 46139
A30: 46140 | B30: 2 | C30: 2 | D30: 1 | F30: 1 | G30: 1 | H30: 2 | J30: 1 | K30: 2 | M30: 46140 | N30: =1500 -> 1500 | P30: Rihan + Ariyan | Q30: Fish + Veggies
A31: 46141 | B31: 2 | C31: 2 | D31: 1 | F31: 1 | G31: 1 | H31: 2 | J31: 1 | K31: 2 | M31: 46141 | N31: =360 -> 360 | P31: Nafis | Q31: Chicken
A32: 46142 | B32: 2 | C32: 2 | D32: 1 | F32: 1 | G32: 1 | H32: 2 | J32: 1 | K32: 2 | M32: 46142 | N32: =235 -> 235 | P32: Tanvir | Q32: Veggies
A33: 46143 | M33: 46143 | N33: =-500 -> -500 | P33: Leftover
A34: Total | B34: =SUM(B2:B33) -> 53 | C34: =SUM(C2:C33) -> 52 | D34: =SUM(D2:D33) -> 18 | E34: =SUM(E2:E33) -> 0 | F34: =SUM(F2:F33) -> 9 | G34: =SUM(G2:G33) -> 37 | H34: =SUM(H2:H33) -> 56 | I34: =SUM(I2:I33) -> 0 | ... K34: =SUM(K2:K33) -> 39 | M34: Total | N34: =SUM(N3:N33) -> 16498 | P34: BDT
A35: =SUM(B34:K34) -> 305
M37: Balance | N37: =(T13-N34)+ 'March 2026'!N37 -> 500 | P37: BDT

Sheet May 2026
A1: Meal Calculation - Food | M1: Shopping Calculation | S1: Shopping Wallet Status | W1: Meal Rate | AA1: Meal Calculation - Money | AG1: Electricity Calculation | AP1: Utility List | AT1: Utility Calculation
A2: Date | B2: Ariyan | C2: Waythin | D2: Umid | F2: Ayon | G2: Rihan | H2: Safar | I2: Sakib | J2: Tanvir | K2: Nafis | M2: Date | N2: Amount | P2: Responsible | Q2: Note | S2: Name | T2: Amount | U2: Required | X2: =ROUND(N34/A35, 2) -> 59.41 | AA2: Name | AB2: Meal | AC2: Total Cost | AD2: Received | AE2: Give/Take | AG2: Flat | AH2: Member | AI2: AC - Unit | AJ2: AC - Cost | AK2: Normal - Unit | AL2: Normal - Cost | AM2: ( Total Cost / Person) + VAT | AN2: Total | AP2: Name | AQ2: Amount | AR2: Amount +1 | AT2: Members | AU2: Payable | AV2: Paid | AW2: Due
A3: 46143 | B3: 2 | C3: 2 | D3: 1 | F3: 1 | G3: 1 | H3: 2 | J3: 1 | K3: 2 | M3: 46143 | N3: =500 -> 500 | P3: Leftover | S3: Ariyan | T3: =650+2450-3000+150+360+1000+900 -> 2510 | U3: 3000 | AA3: Ariyan | AB3: =B34 -> 51 | AC3: =AB3*X2 -> 3029.91 | AD3: =T3 -> 2510 | AE3: =(AD3-AC3)+'April 2026'!AE3 -> 5785.45 | AG3: Flat 10/B | AH3: Ariyan | AI3: =0 -> 0 | AK3: =(178-43.344) -> 134.656 | AL3: =((75*5.26)+((178-SUM(AI4:AI5)-75)*7.2))/3 -> 274.6744 | AM3: =(AJ3+AL3)+(336+74)/3 -> 411.34107 | AN3: =SUM(AM3:AM5) -> 1546.1 | AP3: Electricity | AQ3: =AN3 -> 1546.1 | AR3: =AN6 -> 1055 | AT3: Ariyan | AU3: =AM3+(AQ4/8)+(AQ5/3)+(AQ6/8)+(AQ7/8) -> 1478.0077 | AV3: =0 -> 0 | AW3: =AV3-AU3 -> -1478.0077
A4: 46144 | B4: 2 | C4: 2 | D4: 1 | F4: 1 | G4: 1 | H4: 2 | J4: 1 | K4: 2 | M4: 46144 | N4: =650+2450 -> 3100 | P4: Ariyan | Q4: Chicken + Rice | S4: Waythin | T4: =4000+985+665+145+100+360+200+240 -> 6695 | U4: 3000 | AA4: Waythin | AB4: =C34 -> 41 | AC4: =AB4*X2 -> 2435.81 | AD4: =T4 -> 6695 | AE4: =(AD4-AC4)+'April 2026'!AE4 -> 1617.43 | AH4: Umid | AI4: =(1940.66-1798.33)/5 -> 28.466 | AJ4: =AI4*7.2 -> 204.9552 | AK4: =(178-43.344)/3 -> 44.885333 | AL4: =((75*5.26)+((178-SUM(AI4:AI5)-75)*7.2))/3 -> 274.6744 | AM4: =(AJ4+AL4)+(336+74)/3 -> 616.29627 | AP4: Maid | AQ4: 6000 | AR4: 0 | AT4: Waythin | AU4: =AM5+(AQ4/8)+(AQ5/3)+(AQ6/8)+(AQ7/8) -> 1585.1293 | AV4: =0 -> 0 | AW4: =AV4-AU4 -> -1585.1293
A5: 46145 | B5: 2 | C5: 2 | D5: 1 | F5: 1 | G5: 1 | H5: 2 | J5: 1 | K5: 2 | M5: 46145 | N5: =20 -> 20 | P5: Nafis | Q5: Garlic | S5: Umid | T5: =1000 -> 1000 | U5: 3000 | AA5: Umid | AB5: =D34 -> 8 | AC5: =AB5*X2 -> 475.28 | AD5: =T5 -> 1000 | AE5: =(AD5-AC5)+'April 2026'!AE5 -> -448.9 | AH5: Waythin | AI5: =(2019.85-1945.46)/5 -> 14.878 | AJ5: =AI5*7.2 -> 107.1216 | AK5: =(178-43.344)/3 -> 44.885333 | AL5: =((75*5.26)+((178-SUM(AI4:AI5)-75)*7.2))/3 -> 274.6744 | AM5: =(AJ5+AL5)+(336+74)/3 -> 518.46267 | AP5: Trash | AQ5: 200 | AR5: 200 | AT5: Umid | AU5: =AM4+(AQ4/8)+(AQ5/3)+(AQ6/8)+(AQ7/8)+333 -> 2015.9629 | AV5: =0 -> 0 | AW5: =AV5-AU5 -> -2015.9629
A6: 46146 | B6: 2 | C6: 2 | D6: 1 | F6: 1 | G6: 1 | H6: 2 | J6: 1 | K6: 2 | M6: 46146 | N6: =985+665 -> 1650 | P6: Waythin | Q6: Fish + Veggies | U6: 3000 | AB6: =E34 -> 0 | AC6: =AB6*X2 -> 0 | AD6: =T6 | AE6: =(AD6-AC6)+'April 2026'!AE6 -> 0 | AG6: Flat 10/C | AH6: Safar | AI6: 0 | AK6: =113/5 -> 22.6 | AL6: =211 -> 211 | AM6: =AJ6+AL6 -> 211 | AN6: =SUM(AM6:AM10) -> 1055 | AP6: Wifi | AQ6: 2000 | AR6: 0 | AT6: Ayon | AU6: =AM7+(AQ4/8)+(AR5/5)+(AQ6/8)+(AQ7/8) -> 1251 | AV6: =0 -> 0 | AW6: =AV6-AU6 -> -1251
A7: 46147 | B7: 2 | C7: 2 | D7: 1 | F7: 1 | G7: 2 | H7: 2 | J7: 1 | K7: 2 | M7: 46147 | S7: Ayon | U7: 3000 | AA7: Ayon | AB7: =F34 -> 15 | AC7: =AB7*X2 -> 891.15 | AD7: =T7 | AE7: =(AD7-AC7)+'April 2026'!AE7 -> -690.11 | AH7: Ayon | AI7: 0 | AK7: =113/5 -> 22.6 | AL7: =211 -> 211 | AM7: =AJ7+AL7 -> 211 | AP7: Gas | AQ7: 0 | AR7: 0 | AT7: Rihan | AU7: =AM8+(AQ4/8)+(AR5/5)+(AQ6/8)+(AQ7/8) -> 1251 | AV7: =0 -> 0 | AW7: =AV7-AU7 -> -1251
A8: 46148 | B8: 4 | C8: 2 | D8: 1 | F8: 1 | G8: 1 | H8: 2 | J8: 1 | K8: 2 | M8: 46148 | S8: Rihan | T8: =1569+467+140 -> 2176 | U8: 3000 | AA8: Rihan | AB8: =G34 -> 22 | AC8: =AB8*X2 -> 1307.02 | AD8: =T8 -> 2176 | AE8: =(AD8-AC8)+'April 2026'!AE8 -> 433.35 | AH8: Rihan | AI8: 0 | AK8: =113/5 -> 22.6 | AL8: =211 -> 211 | AM8: =AJ8+AL8 -> 211 | AT8: Safar | AU8: =AM6+(AQ4/8)+(AR5/5)+(AQ6/8)+(AQ7/8) -> 1251 | AV8: =0 -> 0 | AW8: =AV8-AU8 -> -1251
A9: 46149 | B9: 2 | C9: 1 | F9: 1 | G9: 1 | H9: 1 | J9: 0 | K9: 1 | M9: 46149 | N9: =145+1150 -> 1295 | P9: Ariyan + Waythin | Q9: Chicken + Veggies | S9: Safar | U9: 3000 | AA9: Safar | AB9: =H34 -> 41 | AC9: =AB9*X2 -> 2435.81 | AD9: =T9 | AE9: =(AD9-AC9)+'April 2026'!AE9 -> -6649.08 | AH9: Tanvir | AI9: 0 | AK9: =113/5 -> 22.6 | AL9: =211 -> 211 | AM9: =AJ9+AL9 -> 211 | AT9: Tanvir | AU9: =AM9+(AQ4/8)+(AR5/5)+(AQ6/8)+(AQ7/8) -> 1251 | AV9: =0 -> 0 | AW9: =AV9-AU9 -> -1251
A10: 46150 | B10: 4 | C10: 2 | F10: 1 | H10: 2 | J10: 1 | K10: 1 | M10: 46150 | S10: Sakib | U10: 3000 | AB10: =I34 -> 0 | AC10: =AB10*X2 -> 0 | AD10: =T10 | AE10: =(AD10-AC10)+'April 2026'!AE10 -> 0 | AH10: Nafis | AI10: 0 | AK10: =113/5 -> 22.6 | AL10: =211 -> 211 | AM10: =AJ10+AL10 -> 211 | AT10: Nafis | AU10: =AM10+(AQ4/8)+(AR5/5)+(AQ6/8)+(AQ7/8) -> 1251 | AV10: =0 -> 0 | AW10: =AV10-AU10 -> -1251
A11: 46151 | B11: 4 | C11: 2 | D11: 1 | F11: 1 | H11: 2 | J11: 1 | M11: 46151 | N11: =360 -> 360 | P11: Ariyan | Q11: Eggs | S11: Tanvir | T11: =170 -> 170 | U11: 3000 | AA11: Tanvir | AB11: =J34 -> 25 | AC11: =AB11*X2 -> 1485.25 | AD11: =T11 -> 170 | AE11: =(AD11-AC11)+'April 2026'!AE11 -> 926.7
A12: 46152 | B12: 4 | C12: 2 | D12: 1 | F12: 1 | G12: 1 | H12: 2 | J12: 2 | M12: 46152 | N12: =100+140 -> 240 | P12: Waythin + Rihan | Q12: Veggies | S12: Nafis | T12: =20 -> 20 | U12: 3000 | AA12: Nafis | AB12: =K34 -> 17 | AC12: =AB12*X2 -> 1009.97 | AD12: =T12 -> 20 | AE12: =(AD12-AC12)+'April 2026'!AE12 -> -1092.55
A13: 46153 | B13: 4 | C13: 2 | F13: 1 | G13: 1 | H13: 2 | J13: 2 | M13: 46153 | N13: =1220+470+40 -> 1730 | P13: Rihan | Q13: Fish + Veggies | S13: Total | T13: =SUM(T3:T12) -> 12571 | U13: =SUM(U3:U12) -> 30000 | AA13: Total | AB13: =SUM(AB3:AB12) -> 220 | AC13: =SUM(AC3:AC12) -> 13070.2 | AD13: =SUM(AD3:AD12) -> 12571 | AE13: =CEILING(AD13-AC13, 1)+'April 2026'!AE13 -> 2
A14: 46154 | B14: 2 | C14: 2 | F14: 1 | G14: 2 | H14: 2 | J14: 2 | M14: 46154 | N14: =946 -> 946 | P14: Rihan | Q14: Chicken
A15: 46155 | B15: 2 | C15: 2 | F15: 1 | G15: 2 | H15: 2 | J15: 1 | M15: 46155 | N15: =360 -> 360 | P15: Waythin | Q15: Eggs
A16: 46156 | B16: 2 | C16: 2 | F16: 1 | G16: 1 | H16: 4 | J16: 1 | K16: 1 | M16: 46156 | N16: 360 | P16: Ariyan | Q16: Eggs
A17: 46157 | B17: 2 | C17: 2 | F17: 1 | G17: 1 | H17: 4 | J17: 1 | K17: 1 | M17: 46157 | N17: =200 -> 200 | P17: Waythin | Q17: Veggies
A18: 46158 | B18: 4 | C18: 2 | G18: 1 | J18: 3 | K18: 1 | M18: 46158
A19: 46159 | B19: 4 | C19: 2 | G19: 1 | J19: 1 | M19: 46159 | N19: =240+1170 -> 1410 | P19: Waythin + Tanvir | Q19: Egg+Potato+Chicken+Veggies
A20: 46160 | B20: 2 | C20: 2 | G20: 1 | H20: 2 | J20: 1 | M20: 46160 | N20: =900 -> 900 | P20: Ariyan | Q20: Veggies + Rice
A21: 46161 | B21: 1 | C21: 2 | G21: 1 | H21: 2 | J21: 1 | M21: 46161
A22: 46162 | C22: 2 | G22: 1 | H22: 2 | J22: 1 | M22: 46162
A23: 46163 | C23: 2 | G23: 1 | H23: 2 | J23: 1 | M23: 46163
A24: 46164 | M24: 46164
A25: 46165 | M25: 46165
A26: 46166 | M26: 46166
A27: 46167 | M27: 46167
A28: 46168 | M28: 46168
A29: 46169 | M29: 46169
A30: 46170 | M30: 46170
A31: 46171 | M31: 46171
A32: 46172 | M32: 46172
A33: 46173 | M33: 46173
A34: Total | B34: =SUM(B2:B33) -> 51 | C34: =SUM(C2:C33) -> 41 | D34: =SUM(D2:D33) -> 8 | E34: =SUM(E2:E33) -> 0 | F34: =SUM(F2:F33) -> 15 | G34: =SUM(G2:G33) -> 22 | H34: =SUM(H2:H33) -> 41 | I34: =SUM(I2:I33) -> 0 | ... K34: =SUM(K2:K33) -> 17 | M34: Total | N34: =SUM(N3:N33) -> 13071 | P34: BDT
A35: =SUM(B34:K34) -> 220
M37: Balance | N37: =(T13-N34)+'April 2026'!N37 -> 0 | P37: BDT

Sheet June 2026
A1: Meal Calculation - Food | M1: Shopping Calculation | S1: Shopping Wallet Status | W1: Meal Rate | AA1: Meal Calculation - Money | AG1: Electricity Calculation | AP1: Utility List | AT1: Utility Calculation
A2: Date | B2: Ariyan | C2: Waythin | D2: Sameer | E2: Tahmid | F2: Ayon | G2: Rihan | H2: Safar | I2: Sakib | J2: Tanvir | K2: Nafis | M2: Date | N2: Amount | P2: Responsible | Q2: Note | S2: Name | T2: Amount | U2: Required | X2: =ROUND(N34/A35, 2) -> 56.98 | AA2: Name | AB2: Meal | AC2: Total Cost | AD2: Received | AE2: Give/Take | AG2: Flat | AH2: Member | AI2: AC - Unit | AJ2: AC - Cost | AK2: Normal - Unit | AL2: Normal - Cost | AM2: ( Total Cost / Person) + VAT | AN2: Total | AP2: Name | AQ2: Amount | AR2: Amount +1 | AT2: Members | AU2: Payable | AV2: Paid | AW2: Due
A3: 46174 | M3: 46174 | S3: Ariyan | T3: =4026-448.9+1650+1560+2000-1540-1100-2600-330 -> 3217.1 | U3: 3000 | AA3: Ariyan | AB3: =B34 -> 53 | AC3: =AB3*X2 -> 3019.94 | AD3: =T3 -> 3217.1 | AE3: =(AD3-AC3)+'May 2026'!AE3 -> 5982.61 | AG3: Flat 10/B | AH3: Ariyan | AI3: =0 -> 0 | AK3: =(178-43.344) -> 134.656 | AL3: =((75*5.26)+((178-SUM(AI4:AI5)-75)*7.2))/3 -> 274.6744 | AM3: =(AJ3+AL3)+(336+74)/3 -> 411.34107 | AN3: =SUM(AM3:AM5) -> 1546.1 | AP3: Electricity | AQ3: =5441 -> 5441 | AR3: =2103 -> 2103 | AT3: Ariyan | AU3: =AM3+(AQ4/8)+(AQ5/3)+(AQ6/8)+(AQ7/8) -> 1478.0077 | AV3: =0 -> 0 | AW3: =AV3-AU3 -> -1478.0077
A4: 46175 | M4: 46175 | N4: =3670+356 -> 4026 | P4: Ariyan | Q4: ` | S4: Waythin | T4: =150+50 -> 200 | U4: 3000 | AA4: Waythin | AB4: =C34 -> 50 | AC4: =AB4*X2 -> 2849 | AD4: =T4 -> 200 | AE4: =(AD4-AC4)+'May 2026'!AE4 -> -1031.57 | AH4: Sameer | AI4: =(1940.66-1798.33)/5 -> 28.466 | AJ4: =AI4*7.2 -> 204.9552 | AK4: =(178-43.344)/3 -> 44.885333 | AL4: =((75*5.26)+((178-SUM(AI4:AI5)-75)*7.2))/3 -> 274.6744 | AM4: =(AJ4+AL4)+(336+74)/3 -> 616.29627 | AP4: Maid | AQ4: 6000 | AR4: 0 | AT4: Waythin | AU4: =AM5+(AQ4/8)+(AQ5/3)+(AQ6/8)+(AQ7/8) -> 1585.1293 | AV4: =0 -> 0 | AW4: =AV4-AU4 -> -1585.1293
A5: 46176 | B5: 2 | C5: 2 | G5: 2 | H5: 4 | J5: 3 | M5: 46176 | N5: =200+350 -> 550 | P5: Waythin + Safar | Q5: Vegetable + Maintainence | S5: Sameer | T5: =448.9+2600 -> 3048.9 | U5: 3000 | AA5: Sameer | AB5: =D34 -> 46 | AC5: =AB5*X2 -> 2621.08 | AD5: =T5 -> 3048.9 | AE5: =(AD5-AC5)+'May 2026'!AE5 -> -21.08 | AH5: Waythin | AI5: =(2019.85-1945.46)/5 -> 14.878 | AJ5: =AI5*7.2 -> 107.1216 | AK5: =(178-43.344)/3 -> 44.885333 | AL5: =((75*5.26)+((178-SUM(AI4:AI5)-75)*7.2))/3 -> 274.6744 | AM5: =(AJ5+AL5)+(336+74)/3 -> 518.46267 | AP5: Trash | AQ5: 200 | AR5: 200 | AT5: Umid | AU5: =AM4+(AQ4/8)+(AQ5/3)+(AQ6/8)+(AQ7/8)+333 -> 2015.9629 | AV5: =0 -> 0 | AW5: =AV5-AU5 -> -2015.9629
A6: 46177 | B6: 2 | C6: 2 | G6: 2 | H6: 4 | J6: 3 | M6: 46177 | N6: =1350 -> 1350 | P6: Rihan | Q6: Vegetable + Chicken + Fish | S6: Tahmid | T6: =1540+1000 -> 2540 | U6: 3000 | AA6: Tahmid | AB6: =E34 -> 27 | AC6: =AB6*X2 -> 1538.46 | AD6: =T6 -> 2540 | AE6: =(AD6-AC6)+'May 2026'!AE6 -> 1001.54 | AG6: Flat 10/C | AH6: Safar | AI6: 0 | AK6: =113/5 -> 22.6 | AL6: =211 -> 211 | AM6: =AJ6+AL6 -> 211 | AN6: =SUM(AM6:AM10) -> 1055 | AP6: Wifi | AQ6: 2000 | AR6: 0 | AT6: Ayon | AU6: =AM7+(AQ4/8)+(AR5/5)+(AQ6/8)+(AQ7/8) -> 1251 | AV6: =0 -> 0 | AW6: =AV6-AU6 -> -1251
A7: 46178 | B7: 2 | C7: 2 | G7: 2 | H7: 4 | J7: 5 | M7: 46178 | S7: Ayon | T7: =690 -> 690 | U7: 3000 | AA7: Ayon | AB7: =F34 -> 0 | AC7: =AB7*X2 -> 0 | AD7: =T7 -> 690 | AE7: =(AD7-AC7)+'May 2026'!AE7 -> -0.11 | AH7: Ayon | AI7: 0 | AK7: =113/5 -> 22.6 | AL7: =211 -> 211 | AM7: =AJ7+AL7 -> 211 | AP7: Gas | AQ7: 0 | AR7: 0 | AT7: Rihan | AU7: =AM8+(AQ4/8)+(AR5/5)+(AQ6/8)+(AQ7/8) -> 1251 | AV7: =0 -> 0 | AW7: =AV7-AU7 -> -1251
A8: 46179 | B8: 2 | C8: 2 | G8: 2 | H8: 2 | J8: 4 | M8: 46179 | N8: =350+240+430 -> 1020 | P8: Safar + Tanvir | Q8: Veg + Fish + Chicken | S8: Rihan | T8: =1559 -> 1559 | U8: 3000 | AA8: Rihan | AB8: =G34 -> 32 | AC8: =AB8*X2 -> 1823.36 | AD8: =T8 -> 1559 | AE8: =(AD8-AC8)+'May 2026'!AE8 -> 168.99 | AH8: Rihan | AI8: 0 | AK8: =113/5 -> 22.6 | AL8: =211 -> 211 | AM8: =AJ8+AL8 -> 211 | AT8: Safar | AU8: =AM6+(AQ4/8)+(AR5/5)+(AQ6/8)+(AQ7/8) -> 1251 | AV8: =0 -> 0 | AW8: =AV8-AU8 -> -1251
A9: 46180 | B9: 2 | C9: 2 | D9: 2 | G9: 2 | J9: 4 | M9: 46180 | S9: Safar | T9: =350+350+240+1000+2000+1000 -> 4940 | U9: 3000 | AA9: Safar | AB9: =H34 -> 73 | AC9: =AB9*X2 -> 4159.54 | AD9: =T9 -> 4940 | AE9: =(AD9-AC9)+'May 2026'!AE9 -> -5868.62 | AH9: Tanvir | AI9: 0 | AK9: =113/5 -> 22.6 | AL9: =211 -> 211 | AM9: =AJ9+AL9 -> 211 | AT9: Tanvir | AU9: =AM9+(AQ4/8)+(AR5/5)+(AQ6/8)+(AQ7/8) -> 1251 | AV9: =0 -> 0 | AW9: =AV9-AU9 -> -1251
A10: 46181 | B10: 2 | C10: 2 | D10: 2 | G10: 1 | J10: 4 | M10: 46181 | N10: =540+190 -> 730 | P10: Aiman | Q10: Chicken + Egg | S10: Sakib | U10: 3000 | AB10: =I34 -> 0 | AC10: =AB10*X2 -> 0 | AD10: =T10 | AE10: =(AD10-AC10)+'May 2026'!AE10 -> 0 | AH10: Nafis | AI10: 0 | AK10: =113/5 -> 22.6 | AL10: =211 -> 211 | AM10: =AJ10+AL10 -> 211 | AT10: Nafis | AU10: =AM10+(AQ4/8)+(AR5/5)+(AQ6/8)+(AQ7/8) -> 1251 | AV10: =0 -> 0 | AW10: =AV10-AU10 -> -1251
A11: 46182 | B11: 2 | C11: 2 | D11: 2 | G11: 1 | J11: 3 | M11: 46182 | S11: Tanvir | T11: =1200+150+430+540+190+535+260 -> 3305 | U11: 3000 | AA11: Tanvir | AB11: =J34 -> 63 | AC11: =AB11*X2 -> 3589.74 | AD11: =T11 -> 3305 | AE11: =(AD11-AC11)+'May 2026'!AE11 -> 641.96
A12: 46183 | B12: 2 | C12: 2 | D12: 2 | G12: 1 | H12: 2 | J12: 3 | M12: 46183 | S12: Nafis | T12: =1100 -> 1100 | U12: 3000 | AA12: Nafis | AB12: =K34 -> 0 | AC12: =AB12*X2 -> 0 | AD12: =T12 -> 1100 | AE12: =(AD12-AC12)+'May 2026'!AE12 -> 7.45
A13: 46184 | B13: 2 | C13: 2 | D13: 2 | G13: 1 | H13: 4 | J13: 3 | M13: 46184 | N13: =2849 -> 2849 | P13: Safar + Rihan | Q13: Fish Chicken Veggies | S13: Total | T13: =SUM(T3:T12) -> 20600 | U13: =SUM(U3:U12) -> 30000 | AA13: Total | AB13: =SUM(AB3:AB12) -> 344 | AC13: =SUM(AC3:AC12) -> 19601.12 | AD13: =SUM(AD3:AD12) -> 20600 | AE13: =CEILING(AD13-AC13, 1)+'May 2026'!AE13 -> 1001
A14: 46185 | B14: 2 | C14: 2 | D14: 2 | G14: 1 | H14: 4 | J14: 4 | M14: 46185 | N14: =535 -> 535 | P14: Tanvir | Q14: Veggies Egg
A15: 46186 | B15: 2 | C15: 2 | D15: 2 | G15: 1 | H15: 4 | J15: 2 | M15: 46186
A16: 46187 | C16: 1 | D16: 1 | G16: 1 | H16: 2 | J16: 1 | M16: 46187
A17: 46188 | B17: 2 | C17: 2 | D17: 2 | G17: 1 | H17: 4 | J17: 3 | M17: 46188
A18: 46189 | B18: 2 | C18: 2 | D18: 2 | G18: 1 | H18: 4 | J18: 2 | M18: 46189
A19: 46190 | B19: 2 | C19: 2 | D19: 2 | E19: 2 | G19: 1 | H19: 4 | J19: 2 | M19: 46190 | N19: =2070 -> 2070 | P19: Rihan | Q19: Chicken + Fish + Veggies
A20: 46191 | B20: 2 | C20: 2 | D20: 2 | E20: 2 | G20: 1 | H20: 0 | J20: 2 | M20: 46191
A21: 46192 | B21: 2 | C21: 2 | D21: 2 | E21: 2 | G21: 2 | H21: 2 | J21: 2 | M21: 46192
A22: 46193 | B22: 2 | C22: 0 | D22: 2 | E22: 2 | G22: 2 | H22: 1 | J22: 2 | M22: 46193
A23: 46194 | B23: 2 | C23: 0 | D23: 2 | E23: 2 | G23: 1 | H23: 4 | J23: 2 | M23: 46194 | N23: =2650 -> 2650 | P23: Ariyan | Q23: Rice + Egg
A24: 46195 | B24: 2 | C24: 2 | D24: 2 | E24: 2 | G24: 1 | H24: 4 | J24: 2 | M24: 46195 | N24: =260 -> 260 | P24: Tanvir | Q24: Chicken
A25: 46196 | B25: 2 | C25: 2 | D25: 2 | E25: 2 | G25: 1 | H25: 2 | J25: 2 | M25: 46196
A26: 46197 | B26: 2 | C26: 2 | D26: 2 | E26: 2 | G26: 1 | H26: 2 | J26: 2 | M26: 46197
A27: 46198 | B27: 2 | C27: 2 | D27: 2 | E27: 2 | G27: 1 | H27: 4 | J27: 3 | M27: 46198 | N27: =1560 -> 1560 | P27: Safar | Q27: Chicken + Vegetable
A28: 46199 | B28: 2 | C28: 2 | D28: 2 | E28: 2 | H28: 2 | J28: 0 | M28: 46199
A29: 46200 | B29: 2 | C29: 2 | D29: 2 | E29: 2 | H29: 3 | J29: 0 | M29: 46200
A30: 46201 | B30: 2 | C30: 2 | D30: 2 | E30: 2 | G30: 1 | H30: 2 | J30: 0 | M30: 46201
A31: 46202 | B31: 1 | C31: 1 | D31: 1 | E31: 1 | H31: 2 | M31: 46202 | N31: =2000 -> 2000 | P31: Rihan | Q31: Fish + Chicken + Veggies
A32: 46203 | B32: 2 | C32: 2 | D32: 2 | E32: 2 | G32: 1 | H32: 3 | M32: 46203
A33: 46204 | M33: 46204
A34: Total | B34: =SUM(B2:B33) -> 53 | C34: =SUM(C2:C33) -> 50 | D34: =SUM(D2:D33) -> 46 | E34: =SUM(E2:E33) -> 27 | F34: =SUM(F2:F33) -> 0 | G34: =SUM(G2:G33) -> 32 | H34: =SUM(H2:H33) -> 73 | I34: =SUM(I2:I33) -> 0 | ... K34: =SUM(K2:K33) -> 0 | M34: Total | N34: =SUM(N3:N33) -> 19600 | P34: BDT
A35: =SUM(B34:K34) -> 344
M37: Balance | N37: =(T13-N34)+'May 2026'!N37 -> 1000 | P37: BDT

Sheet July 2026
A1: Meal Calculation - Food | M1: Shopping Calculation | S1: Shopping Wallet Status | W1: Meal Rate | AA1: Meal Calculation - Money | AG1: Electricity Calculation | AP1: Utility List | AT1: Utility Calculation
A2: Date | B2: Ariyan | C2: Waythin | D2: Sameer | E2: Tahmid | F2: Ayon | G2: Rihan | H2: Safar | I2: Sakib | J2: Tanvir | K2: Nafis | M2: Date | N2: Amount | P2: Responsible | Q2: Note | S2: Name | T2: Amount | U2: Required | X2: =ROUND(N34/A35, 2) -> 53.38 | AA2: Name | AB2: Meal | AC2: Total Cost | AD2: Received | AE2: Give/Take | AG2: Flat | AH2: Member | AI2: AC - Unit | AJ2: AC - Cost | AK2: Normal - Unit | AL2: Normal - Cost | AM2: ( Total Cost / Person) + VAT | AN2: Total | AP2: Name | AQ2: Amount | AR2: Amount +1 | AT2: Members | AU2: Payable | AV2: Paid | AW2: Due
A3: 46204 | B3: 2 | C3: 2 | D3: 2 | E3: 2 | G3: 1 | H3: 2 | M3: 46204 | N3: =3000 -> 3000 | S3: Ariyan | T3: =3000+1237+721+1000+1000-3000-2000-5035.8+126.23+65.64+43.02+7.45-104.49 -> -2939.95 | U3: 3000 | AA3: Ariyan | AB3: =B34 -> 57 | AC3: =AB3*X2 -> 3042.66 | AD3: =T3 -> -2939.95 | AE3: =(AD3-AC3)+'June 2026'!AE3 -> 0 | AG3: Flat 10/B | AH3: Ariyan | AI3: =0 -> 0 | AK3: =(178-43.344) -> 134.656 | AL3: =((75*5.26)+((178-SUM(AI4:AI5)-75)*7.2))/3 -> 274.6744 | AM3: =(AJ3+AL3)+(336+74)/3 -> 411.34107 | AN3: =SUM(AM3:AM5) -> 1546.1 | AP3: Electricity | AQ3: =3455 -> 3455 | AR3: =2571 -> 2571 | AT3: Ariyan | AU3: =AM3+(AQ4/8)+(AQ5/3)+(AQ6/8)+(AQ7/8) -> 1478.0077 | AV3: =0 -> 0 | AW3: =AV3-AU3 -> -1478.0077
A4: 46205 | B4: 2 | C4: 2 | D4: 2 | E4: 2 | G4: 1 | H4: 2 | J4: 3 | M4: 46205 | N4: =180 -> 180 | P4: Waythin | Q4: Veggies | S4: Waythin | T4: =1000+180+320+280+1000+455+518.95 -> 3753.95 | U4: 3000 | AA4: Waythin | AB4: =C34 -> 51 | AC4: =AB4*X2 -> 2722.38 | AD4: =T4 -> 3753.95 | AE4: =(AD4-AC4)+'June 2026'!AE4 -> 0 | AH4: Sameer | AI4: =(1940.66-1798.33)/5 -> 28.466 | AJ4: =AI4*7.2 -> 204.9552 | AK4: =(178-43.344)/3 -> 44.885333 | AL4: =((75*5.26)+((178-SUM(AI4:AI5)-75)*7.2))/3 -> 274.6744 | AM4: =(AJ4+AL4)+(336+74)/3 -> 616.29627 | AP4: Maid | AQ4: 6000 | AR4: 0 | AT4: Waythin | AU4: =AM5+(AQ4/8)+(AQ5/3)+(AQ6/8)+(AQ7/8) -> 1585.1293 | AV4: =0 -> 0 | AW4: =AV4-AU4 -> -1585.1293
A5: 46206 | B5: 2 | C5: 2 | D5: 2 | E5: 2 | G5: 2 | H5: 0 | J5: 2 | M5: 46206 | N5: =1000 -> 1000 | P5: Rihan | Q5: Fish | S5: Sameer | T5: =3000-43.02 -> 2956.98 | U5: 3000 | AA5: Sameer | AB5: =D34 -> 55 | AC5: =AB5*X2 -> 2935.9 | AD5: =T5 -> 2956.98 | AE5: =(AD5-AC5)+'June 2026'!AE5 -> 0 | AH5: Waythin | AI5: =(2019.85-1945.46)/5 -> 14.878 | AJ5: =AI5*7.2 -> 107.1216 | AK5: =(178-43.344)/3 -> 44.885333 | AL5: =((75*5.26)+((178-SUM(AI4:AI5)-75)*7.2))/3 -> 274.6744 | AM5: =(AJ5+AL5)+(336+74)/3 -> 518.46267 | AP5: Trash | AQ5: 200 | AR5: 200 | AT5: Umid | AU5: =AM4+(AQ4/8)+(AQ5/3)+(AQ6/8)+(AQ7/8)+333 -> 2015.9629 | AV5: =0 -> 0 | AW5: =AV5-AU5 -> -2015.9629
A6: 46207 | B6: 2 | C6: 2 | D6: 2 | E6: 2 | G6: 2 | H6: 0 | J6: 2 | M6: 46207 | S6: Tahmid | T6: =2000-65.64 -> 1934.36 | U6: 3000 | AA6: Tahmid | AB6: =E34 -> 55 | AC6: =AB6*X2 -> 2935.9 | AD6: =T6 -> 1934.36 | AE6: =(AD6-AC6)+'June 2026'!AE6 -> 0 | AG6: Flat 10/C | AH6: Safar | AI6: 0 | AK6: =113/5 -> 22.6 | AL6: =211 -> 211 | AM6: =AJ6+AL6 -> 211 | AN6: =SUM(AM6:AM10) -> 1055 | AP6: Wifi | AQ6: 2000 | AR6: 0 | AT6: Ayon | AU6: =AM7+(AQ4/8)+(AR5/5)+(AQ6/8)+(AQ7/8) -> 1251 | AV6: =0 -> 0 | AW6: =AV6-AU6 -> -1251
A7: 46208 | B7: 1 | C7: 1 | D7: 1 | E7: 1 | G7: 0 | H7: 0 | J7: 1 | M7: 46208 | N7: =950 -> 950 | P7: Ariyan | Q7: Chicken | S7: Ayon | T7: =500-126.23 -> 373.77 | U7: 3000 | AA7: Ayon | AB7: =F34 -> 7 | AC7: =AB7*X2 -> 373.66 | AD7: =T7 -> 373.77 | AE7: =(AD7-AC7)+'June 2026'!AE7 -> 0 | AH7: Ayon | AI7: 0 | AK7: =113/5 -> 22.6 | AL7: =211 -> 211 | AM7: =AJ7+AL7 -> 211 | AP7: Gas | AQ7: 0 | AR7: 0 | AT7: Rihan | AU7: =AM8+(AQ4/8)+(AR5/5)+(AQ6/8)+(AQ7/8) -> 1251 | AV7: =0 -> 0 | AW7: =AV7-AU7 -> -1251
A8: 46209 | B8: 2 | C8: 2 | D8: 2 | E8: 2 | G8: 1 | H8: 0 | J8: 2 | M8: 46209 | S8: Rihan | T8: =883+1000+243.35 -> 2126.35 | U8: 3000 | AA8: Rihan | AB8: =G34 -> 43 | AC8: =AB8*X2 -> 2295.34 | AD8: =T8 -> 2126.35 | AE8: =(AD8-AC8)+'June 2026'!AE8 -> 0 | AH8: Rihan | AI8: 0 | AK8: =113/5 -> 22.6 | AL8: =211 -> 211 | AM8: =AJ8+AL8 -> 211 | AT8: Safar | AU8: =AM6+(AQ4/8)+(AR5/5)+(AQ6/8)+(AQ7/8) -> 1251 | AV8: =0 -> 0 | AW8: =AV8-AU8 -> -1251
A9: 46210 | B9: 3 | C9: 1 | D9: 2 | E9: 2 | G9: 1 | H9: 0 | J9: 2 | M9: 46210 | S9: Safar | T9: =640+780+5035.8 -> 6455.8 | U9: 3000 | AA9: Safar | AB9: =H34 -> 11 | AC9: =AB9*X2 -> 587.18 | AD9: =T9 -> 6455.8 | AE9: =(AD9-AC9)+'June 2026'!AE9 -> 0 | AH9: Tanvir | AI9: 0 | AK9: =113/5 -> 22.6 | AL9: =211 -> 211 | AM9: =AJ9+AL9 -> 211 | AT9: Tanvir | AU9: =AM9+(AQ4/8)+(AR5/5)+(AQ6/8)+(AQ7/8) -> 1251 | AV9: =0 -> 0 | AW9: =AV9-AU9 -> -1251
A10: 46211 | B10: 2 | C10: 2 | D10: 2 | E10: 2 | G10: 1 | H10: 0 | J10: 2 | M10: 46211 | S10: Sakib | U10: 3000 | AB10: =I34 -> 0 | AC10: =AB10*X2 -> 0 | AD10: =T10 | AE10: =(AD10-AC10)+'June 2026'!AE10 -> 0 | AH10: Nafis | AI10: 0 | AK10: =113/5 -> 22.6 | AL10: =211 -> 211 | AM10: =AJ10+AL10 -> 211 | AO10: E | AP10: 402.32 | AQ10: 770.74 | AT10: Nafis | AU10: =AM10+(AQ4/8)+(AR5/5)+(AQ6/8)+(AQ7/8) -> 1251 | AV10: =0 -> 0 | AW10: =AV10-AU10 -> -1251
A11: 46212 | B11: 2 | C11: 2 | D11: 2 | E11: 2 | G11: 1 | H11: 1 | J11: 2 | M11: 46212 | N11: =280 -> 280 | P11: Waythin | Q11: Egg | S11: Tanvir | T11: =1400+510+350+1000 -> 3260 | U11: 3000 | AA11: Tanvir | AB11: =J34 -> 63 | AC11: =AB11*X2 -> 3362.94 | AD11: =T11 -> 3260 | AE11: =(AD11-AC11)+'June 2026'!AE11 -> 539.02 | AO11: M | AP11: 666.67
A12: 46213 | B12: 2 | C12: 2 | D12: 1 | E12: 1 | G12: 2 | J12: 2 | M12: 46213 | N12: =1500+1000 -> 2500 | P12: Pandamart + Ariyan | Q12: Rice Onion Potato Masala Chicken | S12: Nafis | T12: =-7.45 -> -7.45 | U12: 3000 | AA12: Nafis | AB12: =K34 -> 0 | AC12: =AB12*X2 -> 0 | AD12: =T12 -> -7.45 | AE12: =(AD12-AC12)+'June 2026'!AE12 -> 0 | AO12: W | AP12: 222.22
A13: 46214 | B13: 2 | C13: 2 | D13: 2 | E13: 2 | G13: 2 | H13: 2 | J13: 2 | M13: 46214 | N13: =390 -> 390 | P13: Rihan | Q13: Fish | S13: Total | T13: =SUM(T3:T12) -> 17913.81 | U13: =SUM(U3:U12) -> 30000 | AA13: Total | AB13: =SUM(AB3:AB12) -> 342 | AC13: =SUM(AC3:AC12) -> 18255.96 | AD13: =SUM(AD3:AD12) -> 17913.81 | AE13: =CEILING(AD13-AC13, 1)+'June 2026'!AE13 -> 659
A14: 46215 | B14: 2 | C14: 2 | D14: 2 | E14: 2 | G14: 1 | J14: 2 | M14: 46215
A15: 46216 | B15: 2 | C15: 2 | D15: 2 | E15: 2 | G15: 1 | J15: 2 | M15: 46216
A16: 46217 | B16: 1 | C16: 1 | D16: 1 | E16: 1 | G16: 1 | H16: 1 | J16: 1 | M16: 46217 | N16: =640 -> 640 | P16: Safar | Q16: Chicken | AH16: 1845.61 | AM16: 2169.91
A17: 46218 | B17: 2 | C17: 2 | D17: 2 | E17: 2 | G17: 1 | J17: 2 | M17: 46218 | N17: 2000 | P17: Rihan | Q17: Chicken Fish Veg | AH17: =1918.94 -> 1918.94 | AM17: 2348.24
A18: 46219 | B18: 2 | C18: 2 | D18: 2 | E18: 2 | G18: 1 | J18: 2 | M18: 46219 | AH18: =AH17-AH16 -> 73.33 | AK18: Safar Total | AL18: =AJ19+AJ20 -> 959.45976 | AM18: =AM17-AM16 -> 178.33 | AP18: Waythin Total | AQ18: =AO19+AO20 -> 1892.5895
A19: 46220 | B19: 2 | C19: 2 | D19: 2 | E19: 2 | G19: 2 | J19: 2 | M19: 46220 | N19: =510 -> 510 | P19: Tanvir | Q19: Vegetables Chicken | AI19: Safar | AJ19: =AH18*7.59 -> 556.5747 | AN19: Waythin | AO19: =(60*8.02)+(99*7.59)+(19.33*7.2) -> 1371.786
A20: 46221 | B20: 2 | C20: 2 | D20: 2 | E20: 2 | G20: 2 | J20: 4 | M20: 46221 | N20: 1721 | P20: Ariyan | Q20: Oil Rice Masala | AI20: Per Person | AJ20: =(AR3-AJ19)/5 -> 402.88506 | AN20: Per Person | AO20: =(AQ3-AO19)/4 -> 520.8035
A21: 46222 | B21: 2 | C21: 2 | D21: 2 | E21: 2 | G21: 1 | H21: 1 | J21: 2 | M21: 46222
A22: 46223 | B22: 2 | C22: 2 | D22: 2 | E22: 2 | G22: 2 | J22: 4 | M22: 46223 | N22: =455 -> 455 | P22: Waythin | Q22: Vegetable
A23: 46224 | B23: 2 | C23: 2 | D23: 2 | E23: 2 | G23: 2 | J23: 4 | M23: 46224 | N23: =350 -> 350 | P23: Tanvir | Q23: Chicken
A24: 46225 | B24: 2 | C24: 2 | D24: 2 | E24: 2 | G24: 2 | J24: 4 | M24: 46225 | AL24: Cylinder | AR24: Penalty | AS24: Bua | AT24: Wifi | AU24: Gas | AV24: Total ( Without Electricity )
A25: 46226 | B25: 2 | C25: 2 | D25: 2 | E25: 2 | G25: 1 | J25: 2 | M25: 46226 | AK25: First Half | AL25: =1500/4 -> 375 | AM25: Ariyan | AN25: =AL25+AL26+AL27 -> 736.11111 | AR25: =15000 -> 15000 | AS25: =6000 -> 6000 | AT25: =2000 -> 2000 | AU25: =4000 -> 4000
A26: 46227 | B26: 2 | C26: 2 | D26: 2 | E26: 2 | G26: 2 | J26: 2 | M26: 46227 | N26: =780 -> 780 | P26: Safar | Q26: Chicken | AK26: Second Half | AL26: =1500/6 -> 250 | AM26: Rihan | AN26: =AL25+AL26+AL27 -> 736.11111 | AP26: [Ariyan, Rihan, Ayon, Waythin] | AQ26: Per Person | AR26: =AR25/7 -> 2142.8571 | AS26: =AS25/8 -> 750 | AT26: =AT25/6 -> 333.33333 | AU26: =AN25 -> 736.11111 | AV26: =SUM(AL26,AN26,AR26,AS26,AT26,AU26) -> 4948.4127
A27: 46228 | B27: 2 | C27: 0 | D27: 2 | E27: 2 | G27: 2 | J27: 2 | M27: 46228 | AK27: Third Half | AL27: =1000/9 -> 111.11111 | AM27: Waythin | AN27: =AL25+AL26+AL27 -> 736.11111 | AP27: Safar | AQ27: Per Person | AR27: =AR25/7 -> 2142.8571 | AS27: =AS25/8 -> 750 | AT27: 0 | AU27: =AN31 -> 111.11111 | AV27: =AR27+AS27+AT27+AU27 -> 3003.9683
A28: 46229 | B28: 2 | D28: 2 | E28: 2 | F28: 7 | G28: 2 | H28: 2 | J28: 2 | M28: 46229 | N28: =500+2000+1000 -> 3500 | P28: Ayon + Rihan + Pandamart | Q28: Fish Chicken Rice Dal Egg | AM28: Ayon | AN28: =AL25+AL26+AL27 -> 736.11111 | AP28: Tanvir | AQ28: Per Person | AR28: 0 | AS28: =AS25/8 -> 750 | AT28: =(AT25/6)*2 -> 666.66667 | AU28: =(AN30*2) -> 722.22222 | AV28: =AS28+AT28+AU28+AR28 -> 2138.8889
A29: 46230 | B29: 2 | C29: 2 | D29: 2 | E29: 2 | G29: 2 | J29: 2 | M29: 46230 | AM29: Tanvir | AN29: =AL26+AL27 -> 361.11111 | AP29: [Mahir, Tahmid] | AQ29: Per Person | AR29: 0 | AS29: =AS25/8 -> 750 | AT29: 0 | AU29: =AN31 -> 111.11111 | AV29: =SUM(AR29:AU29) -> 861.11111
A30: 46231 | B30: 2 | C30: 2 | D30: 2 | E30: 2 | G30: 2 | J30: 2 | M30: 46231 | AM30: Aiman | AN30: =AL26+AL27 -> 361.11111
A31: 46232 | B31: 2 | C31: 2 | D31: 2 | E31: 2 | G31: 2 | J31: 2 | M31: 46232 | AM31: Safar | AN31: =AL27 -> 111.11111
A32: 46233 | M32: 46233 | AM32: Mahir | AN32: =AL27 -> 111.11111
A33: 46234 | M33: 46234 | AM33: Tahmid | AN33: =AL27 -> 111.11111
A34: Total | B34: =SUM(B2:B33) -> 57 | C34: =SUM(C2:C33) -> 51 | D34: =SUM(D2:D33) -> 55 | E34: =SUM(E2:E33) -> 55 | F34: =SUM(F2:F33) -> 7 | G34: =SUM(G2:G33) -> 43 | H34: =SUM(H2:H33) -> 11 | I34: =SUM(I2:I33) -> 0 | ... K34: =SUM(K2:K33) -> 0 | M34: Total | N34: =SUM(N3:N33) -> 18256 | P34: BDT | AM34: Total | AN34: =SUM(AN25:AN33) -> 4000
A35: =SUM(B34:K34) -> 342
AP36: PERSON | AQ36: UTILITY COST
M37: Balance | N37: =(T13-N34)+'June 2026'!N37 -> 657.81 | P37: BDT | AP37: Ariyan | AQ37: =CEILING(AV26+AO20, 2) -> 5470 | AS37: 10B Electricity Cost | AT37: =AO20 -> 520.8035
AP38: Waythin | AQ38: =Ceiling(AV26+AQ18, 2) -> 6842 | AS38: Waythin Electricity Cost | AT38: =AQ18 -> 1892.5895
AP39: Mahir | AQ39: =Ceiling(AV29+AO20, 2) -> 1382 | AS39: ELECTRICITY BILL SPLIT
AP40: Tahmid | AQ40: =CEILING(AV29+AO20, 2) -> 1382
...
